Workbook

Sheet TongHop
A1: TỔNG HỢP ĐÁNH GIÁ AI AGENT
A3: Thời điểm chạy | B3: 2026-10-22 01:37:49
A4: Model | B4: qwen2.5:7b
A5: Số lần chạy mỗi câu | B5: 3
A6: File test case | B6: tests\test_cases.xlsx
A7: Chỉ số | B7: Giá trị | C7: Cách tính
A8: Tổng số lượt chạy | B8: =COUNTA(Runs!$A$2:$A$124) | C8: Số dòng trong sheet Runs
A9: Số lượt chạy đúng | B9: =COUNTIF(Runs!$F$2:$F$124,"Đúng") | C9: Kết quả = Đúng
A10: Độ chính xác | B10: =B9/B8 | C10: Lượt đúng / tổng lượt
A11: Chọn đúng công cụ | B11: =IFERROR(COUNTIF(Runs!$G$2:$G$124,"Đúng")/(COUNTIF(Runs!$G$2:$G$124,"Đúng")+COUNTIF(Runs!$G$2:$G$124,"Sai")),"n/a") | C11: Chỉ tính test có tool kỳ vọng
A12: Thời gian phản hồi TB (s) | B12: =AVERAGE(Runs!$H$2:$H$124) | C12: Trung bình
A13: Thời gian phản hồi trung vị (s) | B13: =MEDIAN(Runs!$H$2:$H$124) | C13: Trung vị
A14: Thời gian phản hồi P95 (s) | B14: =PERCENTILE(Runs!$H$2:$H$124,0.95) | C14: Phân vị 95
A15: Thời gian phản hồi lớn nhất (s) | B15: =MAX(Runs!$H$2:$H$124) | C15: Lớn nhất
A16: Tỷ lệ lỗi hệ thống | B16: =COUNTIF(Runs!$J$2:$J$124,"Có")/B8 | C16: Không gọi được LLM / exception
A17: Tỷ lệ lỗi công cụ | B17: =COUNTIF(Runs!$K$2:$K$124,"Có")/B8 | C17: Tool trả về lỗi (kể cả lỗi có chủ đích ở test xử lý lỗi)
A18: Tính nhất quán (trung bình theo câu hỏi) | B18: =AVERAGE(CaHoi!$G$2:$G$42) | C18: Với mỗi câu: tỷ lệ lượt trùng kết quả đa số (cần runs ≥ 2)
A20: THEO NHÓM CÂU HỎI
A21: Nhóm | B21: Số lượt | C21: Số lượt đúng | D21: Độ chính xác | E21: Thời gian TB (s)
A22: Thống kê | B22: =COUNTIF(Runs!$B$2:$B$124,A22) | C22: =COUNTIFS(Runs!$B$2:$B$124,A22,Runs!$F$2:$F$124,"Đúng") | D22: =C22/B22 | E22: =AVERAGEIF(Runs!$B$2:$B$124,A22,Runs!$H$2:$H$124)
A23: Lọc dữ liệu | B23: =COUNTIF(Runs!$B$2:$B$124,A23) | C23: =COUNTIFS(Runs!$B$2:$B$124,A23,Runs!$F$2:$F$124,"Đúng") | D23: =C23/B23 | E23: =AVERAGEIF(Runs!$B$2:$B$124,A23,Runs!$H$2:$H$124)
A24: So sánh | B24: =COUNTIF(Runs!$B$2:$B$124,A24) | C24: =COUNTIFS(Runs!$B$2:$B$124,A24,Runs!$F$2:$F$124,"Đúng") | D24: =C24/B24 | E24: =AVERAGEIF(Runs!$B$2:$B$124,A24,Runs!$H$2:$H$124)
A25: Xu hướng | B25: =COUNTIF(Runs!$B$2:$B$124,A25) | C25: =COUNTIFS(Runs!$B$2:$B$124,A25,Runs!$F$2:$F$124,"Đúng") | D25: =C25/B25 | E25: =AVERAGEIF(Runs!$B$2:$B$124,A25,Runs!$H$2:$H$124)
A26: Biểu đồ | B26: =COUNTIF(Runs!$B$2:$B$124,A26) | C26: =COUNTIFS(Runs!$B$2:$B$124,A26,Runs!$F$2:$F$124,"Đúng") | D26: =C26/B26 | E26: =AVERAGEIF(Runs!$B$2:$B$124,A26,Runs!$H$2:$H$124)
A27: Xử lý lỗi | B27: =COUNTIF(Runs!$B$2:$B$124,A27) | C27: =COUNTIFS(Runs!$B$2:$B$124,A27,Runs!$F$2:$F$124,"Đúng") | D27: =C27/B27 | E27: =AVERAGEIF(Runs!$B$2:$B$124,A27,Runs!$H$2:$H$124)

Sheet CaHoi
A1: ID | B1: Nhóm | C1: Câu hỏi | D1: Số lần chạy | E1: Số lần đúng | F1: Tỷ lệ đúng | G1: Nhất quán | H1: Thời gian TB (s)
A2: TC01 | B2: Thống kê | C2: Tổng doanh số của toàn bộ dữ liệu là bao nhiêu? | D2: =COUNTIF(Runs!$A$2:$A$124,A2) | E2: =COUNTIFS(Runs!$A$2:$A$124,A2,Runs!$F$2:$F$124,"Đúng") | F2: =E2/D2 | G2: =MAX(E2,D2-E2)/D2 | H2: =AVERAGEIF(Runs!$A$2:$A$124,A2,Runs!$H$2:$H$124)
A3: TC02 | B3: Thống kê | C3: Tổng lợi nhuận là bao nhiêu? | D3: =COUNTIF(Runs!$A$2:$A$124,A3) | E3: =COUNTIFS(Runs!$A$2:$A$124,A3,Runs!$F$2:$F$124,"Đúng") | F3: =E3/D3 | G3: =MAX(E3,D3-E3)/D3 | H3: =AVERAGEIF(Runs!$A$2:$A$124,A3,Runs!$H$2:$H$124)
A4: TC03 | B4: Thống kê | C4: Tổng số lượng sản phẩm đã bán ra là bao nhiêu? | D4: =COUNTIF(Runs!$A$2:$A$124,A4) | E4: =COUNTIFS(Runs!$A$2:$A$124,A4,Runs!$F$2:$F$124,"Đúng") | F4: =E4/D4 | G4: =MAX(E4,D4-E4)/D4 | H4: =AVERAGEIF(Runs!$A$2:$A$124,A4,Runs!$H$2:$H$124)
A5: TC04 | B5: Thống kê | C5: Mức chiết khấu trung bình (Discount) trên toàn bộ dữ liệu là bao nhiêu? | D5: =COUNTIF(Runs!$A$2:$A$124,A5) | E5: =COUNTIFS(Runs!$A$2:$A$124,A5,Runs!$F$2:$F$124,"Đúng") | F5: =E5/D5 | G5: =MAX(E5,D5-E5)/D5 | H5: =AVERAGEIF(Runs!$A$2:$A$124,A5,Runs!$H$2:$H$124)
A6: TC05 | B6: Thống kê | C6: Có bao nhiêu đơn hàng (Order ID) khác nhau trong dữ liệu? | D6: =COUNTIF(Runs!$A$2:$A$124,A6) | E6: =COUNTIFS(Runs!$A$2:$A$124,A6,Runs!$F$2:$F$124,"Đúng") | F6: =E6/D6 | G6: =MAX(E6,D6-E6)/D6 | H6: =AVERAGEIF(Runs!$A$2:$A$124,A6,Runs!$H$2:$H$124)
A7: TC06 | B7: Thống kê | C7: Giá trị Sales lớn nhất trên một dòng đơn hàng là bao nhiêu? | D7: =COUNTIF(Runs!$A$2:$A$124,A7) | E7: =COUNTIFS(Runs!$A$2:$A$124,A7,Runs!$F$2:$F$124,"Đúng") | F7: =E7/D7 | G7: =MAX(E7,D7-E7)/D7 | H7: =AVERAGEIF(Runs!$A$2:$A$124,A7,Runs!$H$2:$H$124)
A8: TC07 | B8: Thống kê | C8: Doanh số trung bình trên mỗi dòng đơn hàng của phân khúc Consumer là bao nhiêu? | D8: =COUNTIF(Runs!$A$2:$A$124,A8) | E8: =COUNTIFS(Runs!$A$2:$A$124,A8,Runs!$F$2:$F$124,"Đúng") | F8: =E8/D8 | G8: =MAX(E8,D8-E8)/D8 | H8: =AVERAGEIF(Runs!$A$2:$A$124,A8,Runs!$H$2:$H$124)
A9: TC08 | B9: Thống kê | C9: Tổng doanh số của khu vực West là bao nhiêu? | D9: =COUNTIF(Runs!$A$2:$A$124,A9) | E9: =COUNTIFS(Runs!$A$2:$A$124,A9,Runs!$F$2:$F$124,"Đúng") | F9: =E9/D9 | G9: =MAX(E9,D9-E9)/D9 | H9: =AVERAGEIF(Runs!$A$2:$A$124,A9,Runs!$H$2:$H$124)
A10: TC09 | B10: Lọc dữ liệu | C10: Có bao nhiêu dòng đơn hàng bị lỗ (Profit < 0)? | D10: =COUNTIF(Runs!$A$2:$A$124,A10) | E10: =COUNTIFS(Runs!$A$2:$A$124,A10,Runs!$F$2:$F$124,"Đúng") | F10: =E10/D10 | G10: =MAX(E10,D10-E10)/D10 | H10: =AVERAGEIF(Runs!$A$2:$A$124,A10,Runs!$H$2:$H$124)
A11: TC10 | B11: Lọc dữ liệu | C11: Trong danh mục Furniture có bao nhiêu dòng đơn hàng bị lỗ? | D11: =COUNTIF(Runs!$A$2:$A$124,A11) | E11: =COUNTIFS(Runs!$A$2:$A$124,A11,Runs!$F$2:$F$124,"Đúng") | F11: =E11/D11 | G11: =MAX(E11,D11-E11)/D11 | H11: =AVERAGEIF(Runs!$A$2:$A$124,A11,Runs!$H$2:$H$124)
A12: TC11 | B12: Lọc dữ liệu | C12: Có bao nhiêu dòng đơn hàng thuộc danh mục Technology? | D12: =COUNTIF(Runs!$A$2:$A$124,A12) | E12: =COUNTIFS(Runs!$A$2:$A$124,A12,Runs!$F$2:$F$124,"Đúng") | F12: =E12/D12 | G12: =MAX(E12,D12-E12)/D12 | H12: =AVERAGEIF(Runs!$A$2:$A$124,A12,Runs!$H$2:$H$124)
A13: TC12 | B13: Lọc dữ liệu | C13: Có bao nhiêu dòng đơn hàng Phones ở bang California? Cho xem 3 dòng mẫu. | D13: =COUNTIF(Runs!$A$2:$A$124,A13) | E13: =COUNTIFS(Runs!$A$2:$A$124,A13,Runs!$F$2:$F$124,"Đúng") | F13: =E13/D13 | G13: =MAX(E13,D13-E13)/D13 | H13: =AVERAGEIF(Runs!$A$2:$A$124,A13,Runs!$H$2:$H$124)
... A42: TC41 | B42: Xử lý lỗi | C42: (rỗng) | D42: =COUNTIF(Runs!$A$2:$A$124,A42) | E42: =COUNTIFS(Runs!$A$2:$A$124,A42,Runs!$F$2:$F$124,"Đúng") | F42: =E42/D42 | G42: =MAX(E42,D42-E42)/D42 | H42: =AVERAGEIF(Runs!$A$2:$A$124,A42,Runs!$H$2:$H$124)

Sheet Runs
A1: ID | B1: Nhóm | C1: Lần chạy | D1: Câu hỏi | E1: Kiểu kiểm tra | F1: Kết quả | G1: Đúng tool | H1: Thời gian (s) | I1: Số vòng lặp | J1: Lỗi hệ thống | K1: Lỗi công cụ | L1: Tool đã gọi | M1: Lý do sai/ghi chú | N1: Cần duyệt tay | O1: Duyệt tay (Đúng/Sai) | P1: Câu trả lời
A2: TC01 | B2: Thống kê | C2: 1 | D2: Tổng doanh số của toàn bộ dữ liệu là bao nhiêu? | E2: numeric | F2: Đúng | G2: Đúng | H2: 161.058 | I2: 2 | J2: Không | K2: Không | L2: calculate_metrics | P2: Tổng doanh số của toàn bộ dữ liệu là 2,296,919.28 USD. Dữ liệu bao gồm 9,993 dòng giao dịch từ 5,009 đơn hàng duy nhất.
A3: TC01 | B3: Thống kê | C3: 2 | D3: Tổng doanh số của toàn bộ dữ liệu là bao nhiêu? | E3: numeric | F3: Đúng | G3: Đúng | H3: 33.372 | I3: 2 | J3: Không | K3: Không | L3: calculate_metrics | P3: Tổng doanh số của toàn bộ dữ liệu là 2,296,919.28 USD. Dữ liệu bao gồm 5,009 đơn hàng duy nhất.
A4: TC01 | B4: Thống kê | C4: 3 | D4: Tổng doanh số của toàn bộ dữ liệu là bao nhiêu? | E4: numeric | F4: Đúng | G4: Đúng | H4: 33.127 | I4: 2 | J4: Không | K4: Không | L4: calculate_metrics | P4: Tổng doanh số của toàn bộ dữ liệu là 2,296,919.28 USD. Dữ liệu bao gồm 5,009 đơn hàng duy nhất.
A5: TC02 | B5: Thống kê | C5: 1 | D5: Tổng lợi nhuận là bao nhiêu? | E5: numeric | F5: Đúng | G5: Đúng | H5: 38.154 | I5: 2 | J5: Không | K5: Không | L5: calculate_metrics | P5: Tổng lợi nhuận từ bộ dữ liệu Superstore là 286,408.6 USD. Dữ liệu này bao gồm thông tin từ 9,993 đơn hàng duy nhất.
A6: TC02 | B6: Thống kê | C6: 2 | D6: Tổng lợi nhuận là bao nhiêu? | E6: numeric | F6: Đúng | G6: Đúng | H6: 36.086 | I6: 2 | J6: Không | K6: Không | L6: calculate_metrics | P6: Tổng lợi nhuận từ bộ dữ liệu Superstore là 286,408.6 USD. Dữ liệu này bao gồm thông tin từ 5,009 đơn hàng duy nhất.
A7: TC02 | B7: Thống kê | C7: 3 | D7: Tổng lợi nhuận là bao nhiêu? | E7: numeric | F7: Đúng | G7: Đúng | H7: 36.12 | I7: 2 | J7: Không | K7: Không | L7: calculate_metrics | P7: Tổng lợi nhuận từ bộ dữ liệu Superstore là 286,408.6 USD. Dữ liệu này bao gồm thông tin từ 5,009 đơn hàng duy nhất.
A8: TC03 | B8: Thống kê | C8: 1 | D8: Tổng số lượng sản phẩm đã bán ra là bao nhiêu? | E8: numeric | F8: Đúng | G8: Đúng | H8: 41.305 | I8: 2 | J8: Không | K8: Không | L8: calculate_metrics | P8: Tổng số lượng sản phẩm đã bán ra trong bộ dữ liệu là 37,871 đơn vị. Điều này được tính từ 9,993 đơn hàng duy nhất, với mỗi đơn hàng có thể bao gồm nhiều sản phẩm.
A9: TC03 | B9: Thống kê | C9: 2 | D9: Tổng số lượng sản phẩm đã bán ra là bao nhiêu? | E9: numeric | F9: Đúng | G9: Đúng | H9: 39.586 | I9: 2 | J9: Không | K9: Không | L9: calculate_metrics | P9: Tổng số lượng sản phẩm đã bán ra trong bộ dữ liệu là 37,871 đơn vị. Điều này được tính từ 9,993 đơn hàng duy nhất, với mỗi đơn hàng có thể bao gồm nhiều sản phẩm.
A10: TC03 | B10: Thống kê | C10: 3 | D10: Tổng số lượng sản phẩm đã bán ra là bao nhiêu? | E10: numeric | F10: Đúng | G10: Đúng | H10: 39.342 | I10: 2 | J10: Không | K10: Không | L10: calculate_metrics | P10: Tổng số lượng sản phẩm đã bán ra trong bộ dữ liệu là 37,871 đơn vị. Điều này được tính từ 9,993 đơn hàng duy nhất, với mỗi đơn hàng có thể bao gồm nhiều sản phẩm.
A11: TC04 | B11: Thống kê | C11: 1 | D11: Mức chiết khấu trung bình (Discount) trên toàn bộ dữ liệu là bao nhiêu? | E11: numeric | F11: Đúng | G11: Đúng | H11: 40.364 | I11: 2 | J11: Không | K11: Không | L11: calculate_metrics | P11: Mức chiết khấu trung bình (Discount) trên toàn bộ dữ liệu là khoảng 16%. Điều này có nghĩa là mỗi đơn hàng trong bộ dữ liệu Superstore được áp dụng chiết khấu trung bình là 16%.
A12: TC04 | B12: Thống kê | C12: 2 | D12: Mức chiết khấu trung bình (Discount) trên toàn bộ dữ liệu là bao nhiêu? | E12: numeric | F12: Đúng | G12: Đúng | H12: 37.611 | I12: 2 | J12: Không | K12: Không | L12: calculate_metrics | P12: Mức chiết khấu trung bình (Discount) trên toàn bộ dữ liệu là khoảng 16%. Điều này có nghĩa là mỗi đơn hàng trong bộ dữ liệu Superstore được áp dụng chiết khấu trung bình là 16%.
A13: TC04 | B13: Thống kê | C13: 3 | D13: Mức chiết khấu trung bình (Discount) trên toàn bộ dữ liệu là bao nhiêu? | E13: numeric | F13: Đúng | G13: Đúng | H13: 37.384 | I13: 2 | J13: Không | K13: Không | L13: calculate_metrics | P13: Mức chiết khấu trung bình (Discount) trên toàn bộ dữ liệu là khoảng 16%. Điều này có nghĩa là mỗi đơn hàng trong bộ dữ liệu Superstore được áp dụng chiết khấu trung bình là 16%.
A14: TC05 | B14: Thống kê | C14: 1 | D14: Có bao nhiêu đơn hàng (Order ID) khác nhau trong dữ liệu? | E14: numeric | F14: Đúng | G14: Đúng | H14: 227.171 | I14: 4 | J14: Không | K14: Có | L14: calculate_metrics, query_filter_data, calculate_metrics | P14: Dựa trên kết quả từ công cụ `calculate_metrics`, chúng ta có 5,009 đơn hàng (Order ID) khác nhau trong dữ liệu Superstore. Tổng số đơn hàng khác nhau: 5,009 Đây là số lượng duy nhất của các đơn hàng trong bộ dữ liệu hiện có.
A15: TC05 | B15: Thống kê | C15: 2 | D15: Có bao nhiêu đơn hàng (Order ID) khác nhau trong dữ liệu? | E15: numeric | F15: Sai | G15: Sai | H15: 4.148 | I15: 1 | J15: Có | K15: Không | M15: không gọi tool kỳ vọng ['calculate_metrics'] (đã gọi: không); thiếu số 5009; lỗi hệ thống: không gọi được LLM | P15: Không gọi được mô hình Ollama. Hãy kiểm tra Ollama đang chạy, model 'qwen2.5:7b' đã được tải và tương thích với tool calling. Chi tiết: ConnectError: [WinError 10061] No connection could be made because the target machine actively refused it
A16: TC05 | B16: Thống kê | C16: 3 | D16: Có bao nhiêu đơn hàng (Order ID) khác nhau trong dữ liệu? | E16: numeric | F16: Sai | G16: Sai | H16: 4.062 | I16: 1 | J16: Có | K16: Không | M16: không gọi tool kỳ vọng ['calculate_metrics'] (đã gọi: không); thiếu số 5009; lỗi hệ thống: không gọi được LLM | P16: Không gọi được mô hình Ollama. Hãy kiểm tra Ollama đang chạy, model 'qwen2.5:7b' đã được tải và tương thích với tool calling. Chi tiết: ConnectError: [WinError 10061] No connection could be made because the target machine actively refused it
A17: TC06 | B17: Thống kê | C17: 1 | D17: Giá trị Sales lớn nhất trên một dòng đơn hàng là bao nhiêu? | E17: numeric | F17: Sai | G17: Sai | H17: 3.504 | I17: 1 | J17: Có | K17: Không | M17: không gọi tool kỳ vọng ['calculate_metrics'] (đã gọi: không); thiếu số 22638.48; lỗi hệ thống: không gọi được LLM | P17: Không gọi được mô hình Ollama. Hãy kiểm tra Ollama đang chạy, model 'qwen2.5:7b' đã được tải và tương thích với tool calling. Chi tiết: ConnectError: [WinError 10061] No connection could be made because the target machine actively refused it
A18: TC06 | B18: Thống kê | C18: 2 | D18: Giá trị Sales lớn nhất trên một dòng đơn hàng là bao nhiêu? | E18: numeric | F18: Sai | G18: Sai | H18: 3.359 | I18: 1 | J18: Có | K18: Không | M18: không gọi tool kỳ vọng ['calculate_metrics'] (đã gọi: không); thiếu số 22638.48; lỗi hệ thống: không gọi được LLM | P18: Không gọi được mô hình Ollama. Hãy kiểm tra Ollama đang chạy, model 'qwen2.5:7b' đã được tải và tương thích với tool calling. Chi tiết: ConnectError: [WinError 10061] No connection could be made because the target machine actively refused it
A19: TC06 | B19: Thống kê | C19: 3 | D19: Giá trị Sales lớn nhất trên một dòng đơn hàng là bao nhiêu? | E19: numeric | F19: Sai | G19: Sai | H19: 2.907 | I19: 1 | J19: Có | K19: Không | M19: không gọi tool kỳ vọng ['calculate_metrics'] (đã gọi: không); thiếu số 22638.48; lỗi hệ thống: không gọi được LLM | P19: Không gọi được mô hình Ollama. Hãy kiểm tra Ollama đang chạy, model 'qwen2.5:7b' đã được tải và tương thích với tool calling. Chi tiết: ConnectError: [WinError 10061] No connection could be made because the target machine actively refused it
A20: TC07 | B20: Thống kê | C20: 1 | D20: Doanh số trung bình trên mỗi dòng đơn hàng của phân khúc Consumer là bao nhiêu? | E20: numeric | F20: Sai | G20: Sai | H20: 2.99 | I20: 1 | J20: Có | K20: Không | M20: không gọi tool kỳ vọng ['calculate_metrics'] (đã gọi: không); thiếu số 223.73; lỗi hệ thống: không gọi được LLM | P20: Không gọi được mô hình Ollama. Hãy kiểm tra Ollama đang chạy, model 'qwen2.5:7b' đã được tải và tương thích với tool calling. Chi tiết: ConnectError: [WinError 10061] No connection could be made because the target machine actively refused it
A21: TC07 | B21: Thống kê | C21: 2 | D21: Doanh số trung bình trên mỗi dòng đơn hàng của phân khúc Consumer là bao nhiêu? | E21: numeric | F21: Sai | G21: Sai | H21: 2.918 | I21: 1 | J21: Có | K21: Không | M21: không gọi tool kỳ vọng ['calculate_metrics'] (đã gọi: không); thiếu số 223.73; lỗi hệ thống: không gọi được LLM | P21: Không gọi được mô hình Ollama. Hãy kiểm tra Ollama đang chạy, model 'qwen2.5:7b' đã được tải và tương thích với tool calling. Chi tiết: ConnectError: [WinError 10061] No connection could be made because the target machine actively refused it
A22: TC07 | B22: Thống kê | C22: 3 | D22: Doanh số trung bình trên mỗi dòng đơn hàng của phân khúc Consumer là bao nhiêu? | E22: numeric | F22: Sai | G22: Sai | H22: 2.99 | I22: 1 | J22: Có | K22: Không | M22: không gọi tool kỳ vọng ['calculate_metrics'] (đã gọi: không); thiếu số 223.73; lỗi hệ thống: không gọi được LLM | P22: Không gọi được mô hình Ollama. Hãy kiểm tra Ollama đang chạy, model 'qwen2.5:7b' đã được tải và tương thích với tool calling. Chi tiết: ConnectError: [WinError 10061] No connection could be made because the target machine actively refused it
A23: TC08 | B23: Thống kê | C23: 1 | D23: Tổng doanh số của khu vực West là bao nhiêu? | E23: numeric | F23: Sai | G23: Sai | H23: 3.261 | I23: 1 | J23: Có | K23: Không | M23: không gọi tool kỳ vọng ['calculate_metrics'] (đã gọi: không); thiếu số 725457.76; lỗi hệ thống: không gọi được LLM | P23: Không gọi được mô hình Ollama. Hãy kiểm tra Ollama đang chạy, model 'qwen2.5:7b' đã được tải và tương thích với tool calling. Chi tiết: ConnectError: [WinError 10061] No connection could be made because the target machine actively refused it
A24: TC08 | B24: Thống kê | C24: 2 | D24: Tổng doanh số của khu vực West là bao nhiêu? | E24: numeric | F24: Sai | G24: Sai | H24: 3.803 | I24: 1 | J24: Có | K24: Không | M24: không gọi tool kỳ vọng ['calculate_metrics'] (đã gọi: không); thiếu số 725457.76; lỗi hệ thống: không gọi được LLM | P24: Không gọi được mô hình Ollama. Hãy kiểm tra Ollama đang chạy, model 'qwen2.5:7b' đã được tải và tương thích với tool calling. Chi tiết: ConnectError: [WinError 10061] No connection could be made because the target machine actively refused it
A25: TC08 | B25: Thống kê | C25: 3 | D25: Tổng doanh số của khu vực West là bao nhiêu? | E25: numeric | F25: Sai | G25: Sai | H25: 4.636 | I25: 1 | J25: Có | K25: Không | M25: không gọi tool kỳ vọng ['calculate_metrics'] (đã gọi: không); thiếu số 725457.76; lỗi hệ thống: không gọi được LLM | P25: Không gọi được mô hình Ollama. Hãy kiểm tra Ollama đang chạy, model 'qwen2.5:7b' đã được tải và tương thích với tool calling. Chi tiết: ConnectError: [WinError 10061] No connection could be made because the target machine actively refused it
A26: TC09 | B26: Lọc dữ liệu | C26: 1 | D26: Có bao nhiêu dòng đơn hàng bị lỗ (Profit < 0)? | E26: numeric | F26: Sai | G26: Sai | H26: 6.657 | I26: 1 | J26: Có | K26: Không | M26: không gọi tool kỳ vọng ['query_filter_data'] (đã gọi: không); thiếu số 1870; lỗi hệ thống: không gọi được LLM | P26: Không gọi được mô hình Ollama. Hãy kiểm tra Ollama đang chạy, model 'qwen2.5:7b' đã được tải và tương thích với tool calling. Chi tiết: ConnectError: [WinError 10061] No connection could be made because the target machine actively refused it
... A37: TC12 | B37: Lọc dữ liệu | C37: 3 | D37: Có bao nhiêu dòng đơn hàng Phones ở bang California? Cho xem 3 dòng mẫu. | E37: numeric | F37: Sai | G37: Sai | H37: 3.809 | I37: 1 | J37: Có | K37: Không | M37: không gọi tool kỳ vọng ['query_filter_data'] (đã gọi: không); thiếu số 172; lỗi hệ thống: không gọi được LLM | P37: Không gọi được mô hình Ollama. Hãy kiểm tra Ollama đang chạy, model 'qwen2.5:7b' đã được tải và tương thích với tool calling. Chi tiết: ConnectError: [WinError 10061] No connection could be made because the target machine actively refused it
A38: TC13 | B38: Lọc dữ liệu | C38: 1 | D38: Có bao nhiêu dòng đơn hàng bị lỗ ở khu vực West trong năm 2014? | E38: numeric | F38: Sai | G38: Đúng | H38: 49.219 | I38: 2 | J38: Không | K38: Có | L38: query_filter_data | M38: thiếu số 46 | P38: Trong năm 2014, có 123 dòng đơn hàng bị lỗ ở khu vực West. Đây là kết quả tổng hợp từ toàn bộ dữ liệu mà không lấy mẫu.
A39: TC13 | B39: Lọc dữ liệu | C39: 2 | D39: Có bao nhiêu dòng đơn hàng bị lỗ ở khu vực West trong năm 2014? | E39: numeric | F39: Sai | G39: Đúng | H39: 44.303 | I39: 2 | J39: Không | K39: Có | L39: query_filter_data | M39: thiếu số 46 | P39: Trong năm 2014, có 53 đơn hàng bị lỗ ở khu vực West. Đây là kết quả tổng hợp từ toàn bộ dữ liệu mà không lấy mẫu.
A40: TC13 | B40: Lọc dữ liệu | C40: 3 | D40: Có bao nhiêu dòng đơn hàng bị lỗ ở khu vực West trong năm 2014? | E40: numeric | F40: Sai | G40: Đúng | H40: 44.404 | I40: 2 | J40: Không | K40: Có | L40: query_filter_data | M40: thiếu số 46 | P40: Trong năm 2014, có 53 đơn hàng bị lỗ ở khu vực West. Đây là kết quả tổng hợp từ toàn bộ dữ liệu mà không lấy mẫu.
A41: TC14 | B41: So sánh | C41: 1 | D41: Danh mục nào có doanh số cao nhất và doanh số đó là bao nhiêu? | E41: numeric+keyword | F41: Đúng | G41: Đúng | H41: 57.107 | I41: 2 | J41: Không | K41: Không | L41: calculate_metrics | P41: Danh mục "Technology" có doanh số cao nhất với tổng doanh số là 836,154.02 USD. Tiếp theo là danh mục "Furniture" với doanh số 741,718.36 USD và "Office Supplies" với doanh số 719,046.90 USD.
A42: TC14 | B42: So sánh | C42: 2 | D42: Danh mục nào có doanh số cao nhất và doanh số đó là bao nhiêu? | E42: numeric+keyword | F42: Đúng | G42: Đúng | H42: 53.546 | I42: 2 | J42: Không | K42: Không | L42: calculate_metrics | P42: Danh mục "Technology" có doanh số cao nhất với tổng doanh số là 836,154.02 USD. Tiếp theo là "Furniture" với doanh số 741,718.36 USD và "Office Supplies" với doanh số 719,046.90 USD.
A43: TC14 | B43: So sánh | C43: 3 | D43: Danh mục nào có doanh số cao nhất và doanh số đó là bao nhiêu? | E43: numeric+keyword | F43: Đúng | G43: Đúng | H43: 53.273 | I43: 2 | J43: Không | K43: Không | L43: calculate_metrics | P43: Danh mục "Technology" có doanh số cao nhất với tổng doanh số là 836,154.02 USD. Tiếp theo là "Furniture" với doanh số 741,718.36 USD và "Office Supplies" với doanh số 719,046.90 USD.
A44: TC15 | B44: So sánh | C44: 1 | D44: Danh mục nào có lợi nhuận thấp nhất? Lợi nhuận đó là bao nhiêu? | E44: numeric+keyword | F44: Đúng | G44: Đúng | H44: 71.023 | I44: 2 | J44: Không | K44: Không | L44: calculate_metrics | P44: Dựa trên dữ liệu phân tích, danh mục có lợi nhuận thấp nhất là "Furniture", với tổng lợi nhuận là 18,463.16 USD. Danh mục "Office Supplies" và "Technology" lại có lợi nhuận cao hơn nhiều, lần lượt là 122,490 USD và 145,455.44 USD.
A45: TC15 | B45: So sánh | C45: 2 | D45: Danh mục nào có lợi nhuận thấp nhất? Lợi nhuận đó là bao nhiêu? | E45: numeric+keyword | F45: Đúng | G45: Đúng | H45: 70.917 | I45: 2 | J45: Không | K45: Không | L45: calculate_metrics | P45: Dựa trên dữ liệu phân tích, danh mục có lợi nhuận thấp nhất là "Furniture", với tổng lợi nhuận là 18,463.16 USD. Danh mục "Office Supplies" và "Technology" lại có lợi nhuận cao hơn nhiều, lần lượt là 122,490.00 USD và 145,455.44 USD.
A46: TC15 | B46: So sánh | C46: 3 | D46: Danh mục nào có lợi nhuận thấp nhất? Lợi nhuận đó là bao nhiêu? | E46: numeric+keyword | F46: Đúng | G46: Đúng | H46: 70.888 | I46: 2 | J46: Không | K46: Không | L46: calculate_metrics | P46: Dựa trên dữ liệu phân tích, danh mục có lợi nhuận thấp nhất là "Furniture", với tổng lợi nhuận là 18,463.16 USD. Danh mục "Office Supplies" và "Technology" lại có lợi nhuận cao hơn nhiều, lần lượt là 122,490.00 USD và 145,455.44 USD.
A47: TC16 | B47: So sánh | C47: 1 | D47: So sánh lợi nhuận giữa các khu vực. Khu vực nào có lợi nhuận cao nhất? | E47: numeric+keyword | F47: Đúng | G47: Đúng | H47: 91.062 | I47: 2 | J47: Không | K47: Không | L47: calculate_metrics | P47: Theo dữ liệu từ bộ phận Superstore, lợi nhuận được phân bố như sau giữa các khu vực: - Khu vực Tây (West) có lợi nhuận cao nhất với tổng lợi nhuận là 108,418.31. - Khu vực Đông (East) đứng thứ hai với tổng lợi nhuận là 91,534.56. - Khu vực Trung (Central) xếp thứ ba với tổng lợi nhuận là 39,706.24. - Khu vực Nam (South) có lợi nhuận thấp nhất trong bốn khu vực, với tổng lợi nhuận là 46,749.49. Khu vực Tây (West) là khu vực có lợi nhuận cao nhất.
A48: TC16 | B48: So sánh | C48: 2 | D48: So sánh lợi nhuận giữa các khu vực. Khu vực nào có lợi nhuận cao nhất? | E48: numeric+keyword | F48: Đúng | G48: Đúng | H48: 90.656 | I48: 2 | J48: Không | K48: Không | L48: calculate_metrics | P48: Theo dữ liệu từ bộ phận Superstore, lợi nhuận được phân bố như sau giữa các khu vực: - Khu vực Tây (West) có lợi nhuận cao nhất với tổng số lợi nhuận là 108,418.31. - Khu vực Đông (East) đứng thứ hai với lợi nhuận là 91,534.56. - Khu vực Trung (Central) xếp thứ ba với lợi nhuận là 39,706.24. - Khu vực Nam (South) có lợi nhuận thấp nhất trong số bốn khu vực, với tổng lợi nhuận là 46,749.49. Khu vực Tây (West) là khu vực có lợi nhuận cao nhất.
A49: TC16 | B49: So sánh | C49: 3 | D49: So sánh lợi nhuận giữa các khu vực. Khu vực nào có lợi nhuận cao nhất? | E49: numeric+keyword | F49: Đúng | G49: Đúng | H49: 85.452 | I49: 2 | J49: Không | K49: Không | L49: calculate_metrics | P49: Theo dữ liệu từ bộ phận Superstore, lợi nhuận được phân bố như sau giữa các khu vực: - Khu vực Tây (West) có lợi nhuận cao nhất với tổng số lợi nhuận là 108,418.31. - Khu vực Đông (East) đứng thứ hai với lợi nhuận là 91,534.56. - Khu vực Trung (Central) xếp thứ ba với lợi nhuận là 39,706.24. - Khu vực Nam (South) có lợi nhuận thấp nhất trong số bốn khu vực, với tổng lợi nhuận là 46,749.49. Khu vực Tây (West) là khu vực có lợi nhuận cao nhất.
A50: TC17 | B50: So sánh | C50: 1 | D50: Phân khúc khách hàng nào mang lại doanh số cao nhất? | E50: numeric+keyword | F50: Đúng | G50: Đúng | H50: 98.113 | I50: 2 | J50: Không | K50: Không | L50: calculate_metrics | P50: Phân tích cho thấy phân khúc khách hàng mang lại doanh số cao nhất là **Consumer**, với tổng doanh số là 1,161,401.12 đơn vị. Tiếp theo là phân khúc **Corporate** với 706,146.32 đơn vị và phân khúc **Home Office** với 429,371.84 đơn vị. Doanh số cao nhất của phân khúc **Consumer** cho thấy khách hàng cá nhân hoặc gia đình có xu hướng mua sắm nhiều hơn so với các phân khúc khác. Điều này có thể phản ánh nhu cầu tiêu dùng cá nhân hoặc gia đình cao trong dữ liệu này.
...
